Workbook
Name Bank_credit_to_GDP_ratio__2_year_av._change: OFFSET(INDIRECT("'1.1. SRI PT'!$p$"&'[1]1.1. SRI PT'!$A$1),0,0,COUNTIFS('[1]1.1. SRI PT'!$D:$D,"<>",'[1]1.1. SRI PT'!$D:$D,"<>#N/A")- 1)
Name CI_normalized_pooled_data: OFFSET(INDIRECT("'1.1. SRI PT'!$D$"&'[1]1.1. SRI PT'!$A$1),0,0,COUNTIFS('[1]1.1. SRI PT'!$D:$D,"<>",'[1]1.1. SRI PT'!$D:$D,"<>#N/A") - 1)
Name CI_normalized_with_country_data: OFFSET(INDIRECT("'1.1. SRI PT'!$E$"&'[1]1.1. SRI PT'!$A$1),0,0,COUNTIFS('[1]1.1. SRI PT'!$E:$E,"<>",'[1]1.1. SRI PT'!$E:$E,"<>#N/A") - 1)
Name CI_normalized_with_country_data_real_time: OFFSET(INDIRECT("'1.1. SRI PT'!$G$"&'[1]1.1. SRI PT'!$A$1),0,0,COUNTIFS('[1]1.1. SRI PT'!$G:$G,"<>",'[1]1.1. SRI PT'!$G:$G,"<>#N/A") - 1)
Name CI_normalized_with_pooled_data__average_weights: OFFSET(INDIRECT("'1.1. SRI PT'!$U$"&'[1]1.1. SRI PT'!$A$1),0,0,COUNTIFS('[1]1.1. SRI PT'!#REF!,"<>",'[1]1.1. SRI PT'!#REF!,"<>#N/A") - 1)
Name CI_normalized_with_pooled_data__average_weights: OFFSET(INDIRECT("'1.1. SRI PT'!$U$"&'[1]1.1. SRI PT'!$A$1),0,0,COUNTIFS('[1]1.1. SRI PT'!#REF!,"<>",'[1]1.1. SRI PT'!#REF!,"<>#N/A") - 1)
Name CI_normalized_with_pooled_data_real_time: OFFSET(INDIRECT("'1.1. SRI PT'!$F$"&'[1]1.1. SRI PT'!$A$1),0,0,COUNTIFS('[1]1.1. SRI PT'!$F:$F,"<>",'[1]1.1. SRI PT'!$F:$F,"<>#N/A") - 1)
Name Crisis_onset: OFFSET(INDIRECT("'aux'!$B$"&[1]aux!$I$1),0,0,COUNTIFS('[1]1.1. SRI PT'!$D:$D,"<>",'[1]1.1. SRI PT'!$D:$D,"<>#N/A")- 1)
Name Current_account_to_GDP: OFFSET(INDIRECT("'1.1. SRI PT'!$s$"&'[1]1.1. SRI PT'!$A$1),0,0,COUNTIFS('[1]1.1. SRI PT'!$D:$D,"<>",'[1]1.1. SRI PT'!$D:$D,"<>#N/A")- 1)
Name date: OFFSET(INDIRECT("'1.1. SRI PT'!$C$"&'[1]1.1. SRI PT'!$A$1),0,0,COUNTIFS('[1]1.1. SRI PT'!$D:$D,"<>",'[1]1.1. SRI PT'!$D:$D,"<>#N/A")- 1)
Name date2: OFFSET(INDIRECT("'aux'!$A$"&[1]aux!$I$1),0,0,COUNTIFS('[1]1.1. SRI PT'!$D:$D,"<>",'[1]1.1. SRI PT'!$D:$D,"<>#N/A")- 1)
Name dateT: OFFSET(INDIRECT("'1.1. SRI PT'!$T$"&'[1]1.1. SRI PT'!$A$1),0,0,COUNTIFS('[1]1.1. SRI PT'!$D:$D,"<>",'[1]1.1. SRI PT'!$D:$D,"<>#N/A")- 1)
Name Debt_service_ratio__2_year_av._change: OFFSET(INDIRECT("'1.1. SRI PT'!$r$"&'[1]1.1. SRI PT'!$A$1),0,0,COUNTIFS('[1]1.1. SRI PT'!$D:$D,"<>",'[1]1.1. SRI PT'!$D:$D,"<>#N/A")- 1)
Name Evaluation_period: OFFSET(INDIRECT("'aux'!$C$"&[1]aux!$I$1),0,0,COUNTIFS('[1]1.1. SRI PT'!$D:$D,"<>",'[1]1.1. SRI PT'!$D:$D,"<>#N/A")- 1)
Name Low_threshold: OFFSET(INDIRECT("'aux'!$D$"&[1]aux!$I$1),0,0,COUNTIFS('[1]1.1. SRI PT'!$D:$D,"<>",'[1]1.1. SRI PT'!$D:$D,"<>#N/A")- 1)
Name Medium_threshold: OFFSET(INDIRECT("'aux'!$E$"&[1]aux!$I$1),0,0,COUNTIFS('[1]1.1. SRI PT'!$D:$D,"<>",'[1]1.1. SRI PT'!$D:$D,"<>#N/A")- 1)
Name Real_total_credit__2_year_av._growth: OFFSET(INDIRECT("'1.1. SRI PT'!$o$"&'[1]1.1. SRI PT'!$A$1),0,0,COUNTIFS('[1]1.1. SRI PT'!$D:$D,"<>",'[1]1.1. SRI PT'!$D:$D,"<>#N/A")- 1)
Name RRE_price_to_income_ratio__3_year_av._change: OFFSET(INDIRECT("'1.1. SRI PT'!$q$"&'[1]1.1. SRI PT'!$A$1),0,0,COUNTIFS('[1]1.1. SRI PT'!$D:$D,"<>",'[1]1.1. SRI PT'!$D:$D,"<>#N/A")- 1)

Sheet Scoreboard
C1: 2022Q1 | D1: C1 | E1: C2 | F1: C3 | G1: C4 | H1: C5 | I1: C6 | J1: C7 | K1: C8 | L1: C9 | M1: C10 | N1: C11
C2: ="Date:" &C1 -> Date:2022Q1
D3: ="Cálculos do Banco de Portugal - Tabela com dados para " & C1 -> Cálculos do Banco de Portugal - Tabela com dados para 2022Q1
D4: Indicators
C5: Country | D5: Bank credit-to-GDP ratio, 2-year av. change | E5: Real total credit, 2-year av. Growth | F5: Current account balance, % of GDP | G5: NFPS lending spreads, 2-year av. Change | H5: Bank credit-to-GDP gap | I5: Total credit-to-GDP gap | J5: Loans to HHs for house purchases, 3-year av. Growth | K5: HH debt, % of income | L5: RRE price-to-income ratio, 3-year av. growth | M5: Real house price growth, 3-year av. Growth | N5: Debt service ratio, 2-year av. Change
B6: AT | C6: Austria | D6: =VLOOKUP($B6&$C$1,data_stata!$A:$P,MATCH(Scoreboard!D$1,data_stata!$A$1:$P$1,0),FALSE) -> 2.4189949 | E6: =VLOOKUP($B6&$C$1,data_stata!$A:$P,MATCH(Scoreboard!E$1,data_stata!$A$1:$P$1,0),FALSE) -> 0.82022309 | F6: =VLOOKUP($B6&$C$1,data_stata!$A:$P,MATCH(Scoreboard!F$1,data_stata!$A$1:$P$1,0),FALSE) -> -0.0079380581 | G6: =VLOOKUP($B6&$C$1,data_stata!$A:$P,MATCH(Scoreboard!G$1,data_stata!$A$1:$P$1,0),FALSE) -> 0.041655581 | H6: =VLOOKUP($B6&$C$1,data_stata!$A:$P,MATCH(Scoreboard!H$1,data_stata!$A$1:$P$1,0),FALSE) -> 3.7858102 | I6: =VLOOKUP($B6&$C$1,data_stata!$A:$P,MATCH(Scoreboard!I$1,data_stata!$A$1:$P$1,0),FALSE) -> 0.0011330439 | J6: =VLOOKUP($B6&$C$1,data_stata!$A:$P,MATCH(Scoreboard!J$1,data_stata!$A$1:$P$1,0),FALSE) -> 3.7871227 | K6: =VLOOKUP($B6&$C$1,data_stata!$A:$P,MATCH(Scoreboard!K$1,data_stata!$A$1:$P$1,0),FALSE) -> 86.340889 | ... N6: =VLOOKUP($B6&$C$1,data_stata!$A:$P,MATCH(Scoreboard!N$1,data_stata!$A$1:$P$1,0),FALSE) -> 0.10050106
B7: BE | C7: Belgium | D7: =VLOOKUP($B7&$C$1,data_stata!$A:$P,MATCH(Scoreboard!D$1,data_stata!$A$1:$P$1,0),FALSE) -> -0.01348877 | E7: =VLOOKUP($B7&$C$1,data_stata!$A:$P,MATCH(Scoreboard!E$1,data_stata!$A$1:$P$1,0),FALSE) -> 0.12804413 | F7: =VLOOKUP($B7&$C$1,data_stata!$A:$P,MATCH(Scoreboard!F$1,data_stata!$A$1:$P$1,0),FALSE) -> -0.69614112 | G7: =VLOOKUP($B7&$C$1,data_stata!$A:$P,MATCH(Scoreboard!G$1,data_stata!$A$1:$P$1,0),FALSE) -> 0.080625445 | H7: =VLOOKUP($B7&$C$1,data_stata!$A:$P,MATCH(Scoreboard!H$1,data_stata!$A$1:$P$1,0),FALSE) -> -3.3723118 | I7: =VLOOKUP($B7&$C$1,data_stata!$A:$P,MATCH(Scoreboard!I$1,data_stata!$A$1:$P$1,0),FALSE) -> -18.684326 | J7: =VLOOKUP($B7&$C$1,data_stata!$A:$P,MATCH(Scoreboard!J$1,data_stata!$A$1:$P$1,0),FALSE) -> 6.2709517 | K7: =VLOOKUP($B7&$C$1,data_stata!$A:$P,MATCH(Scoreboard!K$1,data_stata!$A$1:$P$1,0),FALSE) -> 106.14912 | ... N7: =VLOOKUP($B7&$C$1,data_stata!$A:$P,MATCH(Scoreboard!N$1,data_stata!$A$1:$P$1,0),FALSE) -> -0.43176937
B8: CY | C8: Cyprus | D8: =VLOOKUP($B8&$C$1,data_stata!$A:$P,MATCH(Scoreboard!D$1,data_stata!$A$1:$P$1,0),FALSE) -> -17.867874 | E8: =VLOOKUP($B8&$C$1,data_stata!$A:$P,MATCH(Scoreboard!E$1,data_stata!$A$1:$P$1,0),FALSE) -> -2.6303473 | F8: =VLOOKUP($B8&$C$1,data_stata!$A:$P,MATCH(Scoreboard!F$1,data_stata!$A$1:$P$1,0),FALSE) -> -7.8746452 | G8: =VLOOKUP($B8&$C$1,data_stata!$A:$P,MATCH(Scoreboard!G$1,data_stata!$A$1:$P$1,0),FALSE) -> -0.0010982448 | H8: =VLOOKUP($B8&$C$1,data_stata!$A:$P,MATCH(Scoreboard!H$1,data_stata!$A$1:$P$1,0),FALSE) -> -64.152016 | I8: =VLOOKUP($B8&$C$1,data_stata!$A:$P,MATCH(Scoreboard!I$1,data_stata!$A$1:$P$1,0),FALSE) -> -71.318222 | J8: =VLOOKUP($B8&$C$1,data_stata!$A:$P,MATCH(Scoreboard!J$1,data_stata!$A$1:$P$1,0),FALSE) -> -2.8121607 | K8: =VLOOKUP($B8&$C$1,data_stata!$A:$P,MATCH(Scoreboard!K$1,data_stata!$A$1:$P$1,0),FALSE) -> 0 | ... N8: =VLOOKUP($B8&$C$1,data_stata!$A:$P,MATCH(Scoreboard!N$1,data_stata!$A$1:$P$1,0),FALSE) -> -1.6748018
B9: DE | C9: Germany | D9: =VLOOKUP($B9&$C$1,data_stata!$A:$P,MATCH(Scoreboard!D$1,data_stata!$A$1:$P$1,0),FALSE) -> 1.6624985 | E9: =VLOOKUP($B9&$C$1,data_stata!$A:$P,MATCH(Scoreboard!E$1,data_stata!$A$1:$P$1,0),FALSE) -> 2.0945835 | F9: =VLOOKUP($B9&$C$1,data_stata!$A:$P,MATCH(Scoreboard!F$1,data_stata!$A$1:$P$1,0),FALSE) -> 6.5920005 | G9: =VLOOKUP($B9&$C$1,data_stata!$A:$P,MATCH(Scoreboard!G$1,data_stata!$A$1:$P$1,0),FALSE) -> 0.27494881 | H9: =VLOOKUP($B9&$C$1,data_stata!$A:$P,MATCH(Scoreboard!H$1,data_stata!$A$1:$P$1,0),FALSE) -> 7.1283059 | I9: =VLOOKUP($B9&$C$1,data_stata!$A:$P,MATCH(Scoreboard!I$1,data_stata!$A$1:$P$1,0),FALSE) -> 10.17368 | J9: =VLOOKUP($B9&$C$1,data_stata!$A:$P,MATCH(Scoreboard!J$1,data_stata!$A$1:$P$1,0),FALSE) -> 3.594506 | K9: =VLOOKUP($B9&$C$1,data_stata!$A:$P,MATCH(Scoreboard!K$1,data_stata!$A$1:$P$1,0),FALSE) -> 91.701042 | ... N9: =VLOOKUP($B9&$C$1,data_stata!$A:$P,MATCH(Scoreboard!N$1,data_stata!$A$1:$P$1,0),FALSE) -> 0.027908325
B10: EE | C10: Estonia | D10: =VLOOKUP($B10&$C$1,data_stata!$A:$P,MATCH(Scoreboard!D$1,data_stata!$A$1:$P$1,0),FALSE) -> -1.4638519 | E10: =VLOOKUP($B10&$C$1,data_stata!$A:$P,MATCH(Scoreboard!E$1,data_stata!$A$1:$P$1,0),FALSE) -> 0.72803152 | F10: =VLOOKUP($B10&$C$1,data_stata!$A:$P,MATCH(Scoreboard!F$1,data_stata!$A$1:$P$1,0),FALSE) -> -0.17791331 | G10: =VLOOKUP($B10&$C$1,data_stata!$A:$P,MATCH(Scoreboard!G$1,data_stata!$A$1:$P$1,0),FALSE) -> 0.14534177 | H10: =VLOOKUP($B10&$C$1,data_stata!$A:$P,MATCH(Scoreboard!H$1,data_stata!$A$1:$P$1,0),FALSE) -> 3.2695143 | I10: =VLOOKUP($B10&$C$1,data_stata!$A:$P,MATCH(Scoreboard!I$1,data_stata!$A$1:$P$1,0),FALSE) -> -8.8485165 | J10: =VLOOKUP($B10&$C$1,data_stata!$A:$P,MATCH(Scoreboard!J$1,data_stata!$A$1:$P$1,0),FALSE) -> 3.1121044 | K10: =VLOOKUP($B10&$C$1,data_stata!$A:$P,MATCH(Scoreboard!K$1,data_stata!$A$1:$P$1,0),FALSE) -> 0 | ... N10: =VLOOKUP($B10&$C$1,data_stata!$A:$P,MATCH(Scoreboard!N$1,data_stata!$A$1:$P$1,0),FALSE) -> -0.71865797
B11: ES | C11: Spain | D11: =VLOOKUP($B11&$C$1,data_stata!$A:$P,MATCH(Scoreboard!D$1,data_stata!$A$1:$P$1,0),FALSE) -> -0.73579788 | E11: =VLOOKUP($B11&$C$1,data_stata!$A:$P,MATCH(Scoreboard!E$1,data_stata!$A$1:$P$1,0),FALSE) -> 0.58543235 | F11: =VLOOKUP($B11&$C$1,data_stata!$A:$P,MATCH(Scoreboard!F$1,data_stata!$A$1:$P$1,0),FALSE) -> 0.63626051 | G11: =VLOOKUP($B11&$C$1,data_stata!$A:$P,MATCH(Scoreboard!G$1,data_stata!$A$1:$P$1,0),FALSE) -> -0.014242012 | H11: =VLOOKUP($B11&$C$1,data_stata!$A:$P,MATCH(Scoreboard!H$1,data_stata!$A$1:$P$1,0),FALSE) -> -10.800853 | I11: =VLOOKUP($B11&$C$1,data_stata!$A:$P,MATCH(Scoreboard!I$1,data_stata!$A$1:$P$1,0),FALSE) -> -13.734506 | J11: =VLOOKUP($B11&$C$1,data_stata!$A:$P,MATCH(Scoreboard!J$1,data_stata!$A$1:$P$1,0),FALSE) -> -3.1441481 | K11: =VLOOKUP($B11&$C$1,data_stata!$A:$P,MATCH(Scoreboard!K$1,data_stata!$A$1:$P$1,0),FALSE) -> 91.983093 | ... N11: =VLOOKUP($B11&$C$1,data_stata!$A:$P,MATCH(Scoreboard!N$1,data_stata!$A$1:$P$1,0),FALSE) -> 0.15030575
B12: FI | C12: Finland | D12: =VLOOKUP($B12&$C$1,data_stata!$A:$P,MATCH(Scoreboard!D$1,data_stata!$A$1:$P$1,0),FALSE) -> -0.020896912 | E12: =VLOOKUP($B12&$C$1,data_stata!$A:$P,MATCH(Scoreboard!E$1,data_stata!$A$1:$P$1,0),FALSE) -> -1.0590265 | F12: =VLOOKUP($B12&$C$1,data_stata!$A:$P,MATCH(Scoreboard!F$1,data_stata!$A$1:$P$1,0),FALSE) -> 0.096578471 | G12: =VLOOKUP($B12&$C$1,data_stata!$A:$P,MATCH(Scoreboard!G$1,data_stata!$A$1:$P$1,0),FALSE) -> -0.11511082 | H12: =VLOOKUP($B12&$C$1,data_stata!$A:$P,MATCH(Scoreboard!H$1,data_stata!$A$1:$P$1,0),FALSE) -> -7.1361656 | I12: =VLOOKUP($B12&$C$1,data_stata!$A:$P,MATCH(Scoreboard!I$1,data_stata!$A$1:$P$1,0),FALSE) -> -19.918562 | J12: =VLOOKUP($B12&$C$1,data_stata!$A:$P,MATCH(Scoreboard!J$1,data_stata!$A$1:$P$1,0),FALSE) -> 0.9790653 | K12: =VLOOKUP($B12&$C$1,data_stata!$A:$P,MATCH(Scoreboard!K$1,data_stata!$A$1:$P$1,0),FALSE) -> 119.13233 | ... N12: =VLOOKUP($B12&$C$1,data_stata!$A:$P,MATCH(Scoreboard!N$1,data_stata!$A$1:$P$1,0),FALSE) -> -0.25097179
B13: FR | C13: France | D13: =VLOOKUP($B13&$C$1,data_stata!$A:$P,MATCH(Scoreboard!D$1,data_stata!$A$1:$P$1,0),FALSE) -> 3.6133308 | E13: =VLOOKUP($B13&$C$1,data_stata!$A:$P,MATCH(Scoreboard!E$1,data_stata!$A$1:$P$1,0),FALSE) -> 2.7984676 | F13: =VLOOKUP($B13&$C$1,data_stata!$A:$P,MATCH(Scoreboard!F$1,data_stata!$A$1:$P$1,0),FALSE) -> 0.24822722 | G13: =VLOOKUP($B13&$C$1,data_stata!$A:$P,MATCH(Scoreboard!G$1,data_stata!$A$1:$P$1,0),FALSE) -> -0.0051082121 | H13: =VLOOKUP($B13&$C$1,data_stata!$A:$P,MATCH(Scoreboard!H$1,data_stata!$A$1:$P$1,0),FALSE) -> 1.8165748 | I13: =VLOOKUP($B13&$C$1,data_stata!$A:$P,MATCH(Scoreboard!I$1,data_stata!$A$1:$P$1,0),FALSE) -> 3.1520116 | J13: =VLOOKUP($B13&$C$1,data_stata!$A:$P,MATCH(Scoreboard!J$1,data_stata!$A$1:$P$1,0),FALSE) -> 4.4464355 | K13: =VLOOKUP($B13&$C$1,data_stata!$A:$P,MATCH(Scoreboard!K$1,data_stata!$A$1:$P$1,0),FALSE) -> 103.49734 | ... N13: =VLOOKUP($B13&$C$1,data_stata!$A:$P,MATCH(Scoreboard!N$1,data_stata!$A$1:$P$1,0),FALSE) -> 0.37966824
B14: GR | C14: Greece | D14: =VLOOKUP($B14&$C$1,data_stata!$A:$P,MATCH(Scoreboard!D$1,data_stata!$A$1:$P$1,0),FALSE) -> -11.549681 | E14: =VLOOKUP($B14&$C$1,data_stata!$A:$P,MATCH(Scoreboard!E$1,data_stata!$A$1:$P$1,0),FALSE) -> 2.405977 | F14: =VLOOKUP($B14&$C$1,data_stata!$A:$P,MATCH(Scoreboard!F$1,data_stata!$A$1:$P$1,0),FALSE) -> -7.7358937 | G14: =VLOOKUP($B14&$C$1,data_stata!$A:$P,MATCH(Scoreboard!G$1,data_stata!$A$1:$P$1,0),FALSE) -> 0.056762572 | H14: =VLOOKUP($B14&$C$1,data_stata!$A:$P,MATCH(Scoreboard!H$1,data_stata!$A$1:$P$1,0),FALSE) -> -42.934139 | I14: =VLOOKUP($B14&$C$1,data_stata!$A:$P,MATCH(Scoreboard!I$1,data_stata!$A$1:$P$1,0),FALSE) -> -19.774176 | J14: =VLOOKUP($B14&$C$1,data_stata!$A:$P,MATCH(Scoreboard!J$1,data_stata!$A$1:$P$1,0),FALSE) -> -16.154646 | K14: =VLOOKUP($B14&$C$1,data_stata!$A:$P,MATCH(Scoreboard!K$1,data_stata!$A$1:$P$1,0),FALSE) -> 0 | ... N14: =VLOOKUP($B14&$C$1,data_stata!$A:$P,MATCH(Scoreboard!N$1,data_stata!$A$1:$P$1,0),FALSE) -> 0
B15: IE | C15: Ireland | D15: =VLOOKUP($B15&$C$1,data_stata!$A:$P,MATCH(Scoreboard!D$1,data_stata!$A$1:$P$1,0),FALSE) -> -4.6886559 | E15: =VLOOKUP($B15&$C$1,data_stata!$A:$P,MATCH(Scoreboard!E$1,data_stata!$A$1:$P$1,0),FALSE) -> 0 | F15: =VLOOKUP($B15&$C$1,data_stata!$A:$P,MATCH(Scoreboard!F$1,data_stata!$A$1:$P$1,0),FALSE) -> 13.715785 | G15: =VLOOKUP($B15&$C$1,data_stata!$A:$P,MATCH(Scoreboard!G$1,data_stata!$A$1:$P$1,0),FALSE) -> 0.24756618 | H15: =VLOOKUP($B15&$C$1,data_stata!$A:$P,MATCH(Scoreboard!H$1,data_stata!$A$1:$P$1,0),FALSE) -> -9.9307671 | I15: =VLOOKUP($B15&$C$1,data_stata!$A:$P,MATCH(Scoreboard!I$1,data_stata!$A$1:$P$1,0),FALSE) -> 0 | J15: =VLOOKUP($B15&$C$1,data_stata!$A:$P,MATCH(Scoreboard!J$1,data_stata!$A$1:$P$1,0),FALSE) -> 2.0619581 | K15: =VLOOKUP($B15&$C$1,data_stata!$A:$P,MATCH(Scoreboard!K$1,data_stata!$A$1:$P$1,0),FALSE) -> 99.915932 | ... N15: =VLOOKUP($B15&$C$1,data_stata!$A:$P,MATCH(Scoreboard!N$1,data_stata!$A$1:$P$1,0),FALSE) -> 0
B16: IT | C16: Italy | D16: =VLOOKUP($B16&$C$1,data_stata!$A:$P,MATCH(Scoreboard!D$1,data_stata!$A$1:$P$1,0),FALSE) -> -2.9806671 | E16: =VLOOKUP($B16&$C$1,data_stata!$A:$P,MATCH(Scoreboard!E$1,data_stata!$A$1:$P$1,0),FALSE) -> -2.5355794 | F16: =VLOOKUP($B16&$C$1,data_stata!$A:$P,MATCH(Scoreboard!F$1,data_stata!$A$1:$P$1,0),FALSE) -> 1.6857507 | G16: =VLOOKUP($B16&$C$1,data_stata!$A:$P,MATCH(Scoreboard!G$1,data_stata!$A$1:$P$1,0),FALSE) -> 0.69603682 | H16: =VLOOKUP($B16&$C$1,data_stata!$A:$P,MATCH(Scoreboard!H$1,data_stata!$A$1:$P$1,0),FALSE) -> -13.272143 | I16: =VLOOKUP($B16&$C$1,data_stata!$A:$P,MATCH(Scoreboard!I$1,data_stata!$A$1:$P$1,0),FALSE) -> -12.979579 | J16: =VLOOKUP($B16&$C$1,data_stata!$A:$P,MATCH(Scoreboard!J$1,data_stata!$A$1:$P$1,0),FALSE) -> 0.62078929 | K16: =VLOOKUP($B16&$C$1,data_stata!$A:$P,MATCH(Scoreboard!K$1,data_stata!$A$1:$P$1,0),FALSE) -> 64.193703 | ... N16: =VLOOKUP($B16&$C$1,data_stata!$A:$P,MATCH(Scoreboard!N$1,data_stata!$A$1:$P$1,0),FALSE) -> -0.36835957
B17: LT | C17: Lithuania | D17: =VLOOKUP($B17&$C$1,data_stata!$A:$P,MATCH(Scoreboard!D$1,data_stata!$A$1:$P$1,0),FALSE) -> -0.45365524 | E17: =VLOOKUP($B17&$C$1,data_stata!$A:$P,MATCH(Scoreboard!E$1,data_stata!$A$1:$P$1,0),FALSE) -> -1.2021061 | F17: =VLOOKUP($B17&$C$1,data_stata!$A:$P,MATCH(Scoreboard!F$1,data_stata!$A$1:$P$1,0),FALSE) -> -1.3280824 | G17: =VLOOKUP($B17&$C$1,data_stata!$A:$P,MATCH(Scoreboard!G$1,data_stata!$A$1:$P$1,0),FALSE) -> -0.19418874 | H17: =VLOOKUP($B17&$C$1,data_stata!$A:$P,MATCH(Scoreboard!H$1,data_stata!$A$1:$P$1,0),FALSE) -> -2.2500827 | I17: =VLOOKUP($B17&$C$1,data_stata!$A:$P,MATCH(Scoreboard!I$1,data_stata!$A$1:$P$1,0),FALSE) -> -9.6022768 | J17: =VLOOKUP($B17&$C$1,data_stata!$A:$P,MATCH(Scoreboard!J$1,data_stata!$A$1:$P$1,0),FALSE) -> 4.387197 | K17: =VLOOKUP($B17&$C$1,data_stata!$A:$P,MATCH(Scoreboard!K$1,data_stata!$A$1:$P$1,0),FALSE) -> 0 | ... N17: =VLOOKUP($B17&$C$1,data_stata!$A:$P,MATCH(Scoreboard!N$1,data_stata!$A$1:$P$1,0),FALSE) -> -0.32414365
... B24: SK | C24: Slovakia | D24: =VLOOKUP($B24&$C$1,data_stata!$A:$P,MATCH(Scoreboard!D$1,data_stata!$A$1:$P$1,0),FALSE) -> 2.5827675 | E24: =VLOOKUP($B24&$C$1,data_stata!$A:$P,MATCH(Scoreboard!E$1,data_stata!$A$1:$P$1,0),FALSE) -> 0.71572202 | F24: =VLOOKUP($B24&$C$1,data_stata!$A:$P,MATCH(Scoreboard!F$1,data_stata!$A$1:$P$1,0),FALSE) -> -4.4924865 | G24: =VLOOKUP($B24&$C$1,data_stata!$A:$P,MATCH(Scoreboard!G$1,data_stata!$A$1:$P$1,0),FALSE) -> 0.049750801 | H24: =VLOOKUP($B24&$C$1,data_stata!$A:$P,MATCH(Scoreboard!H$1,data_stata!$A$1:$P$1,0),FALSE) -> 1.6372415 | I24: =VLOOKUP($B24&$C$1,data_stata!$A:$P,MATCH(Scoreboard!I$1,data_stata!$A$1:$P$1,0),FALSE) -> 4.6875467 | J24: =VLOOKUP($B24&$C$1,data_stata!$A:$P,MATCH(Scoreboard!J$1,data_stata!$A$1:$P$1,0),FALSE) -> 6.3524857 | K24: =VLOOKUP($B24&$C$1,data_stata!$A:$P,MATCH(Scoreboard!K$1,data_stata!$A$1:$P$1,0),FALSE) -> 0 | ... N24: =VLOOKUP($B24&$C$1,data_stata!$A:$P,MATCH(Scoreboard!N$1,data_stata!$A$1:$P$1,0),FALSE) -> -0.096666336
C25: T1 | D25: 0.22 | E25: 2 | F25: -0.8 | G25: 0 | H25: -1 | I25: -1 | J25: 3 | K25: 75 | L25: 0.5 | M25: 2.5 | N25: 0.1
C26: T2 | D26: 1.2 | E26: 4 | F26: -1.5 | G26: -0.1 | H26: 2 | I26: 2 | J26: 6 | K26: 85 | L26: 1.5 | M26: 5 | N26: 0.3
C27: T3 | D27: 2.2 | E27: 6 | F27: -2.3 | G27: -0.15 | H27: 4 | I27: 4 | J27: 9 | K27: 95 | L27: 2.5 | M27: 7.5 | N27: 0.6

Sheet data_stata
A1: vlookup | B1: country | C1: date | D1: year | E1: quarter | F1: C1 | G1: C2 | H1: C3 | I1: C4 | J1: C5 | K1: C6 | L1: C7 | M1: C8 | N1: C9 | O1: C10 | P1: C11
A2: AT1990Q1 | B2: AT | C2: 32874 | D2: 1990 | E2: 1
A3: AT1990Q2 | B3: AT | C3: 32964 | D3: 1990 | E3: 2
A4: AT1990Q3 | B4: AT | C4: 33055 | D4: 1990 | E4: 3
A5: AT1990Q4 | B5: AT | C5: 33147 | D5: 1990 | E5: 4 | H5: 0.81864119
A6: AT1991Q1 | B6: AT | C6: 33239 | D6: 1991 | E6: 1 | H6: 0.68294442
A7: AT1991Q2 | B7: AT | C7: 33329 | D7: 1991 | E7: 2 | H7: 0.34661633
A8: AT1991Q3 | B8: AT | C8: 33420 | D8: 1991 | E8: 3 | H8: 0.14919271
A9: AT1991Q4 | B9: AT | C9: 33512 | D9: 1991 | E9: 4 | H9: 0.080240846
A10: AT1992Q1 | B10: AT | C10: 33604 | D10: 1992 | E10: 1 | H10: 0.52500731
A11: AT1992Q2 | B11: AT | C11: 33695 | D11: 1992 | E11: 2 | H11: 0.71553504
A12: AT1992Q3 | B12: AT | C12: 33786 | D12: 1992 | E12: 3 | H12: 0.39748967
A13: AT1992Q4 | B13: AT | C13: 33878 | D13: 1992 | E13: 4 | H13: -0.0082018003
A14: AT1993Q1 | B14: AT | C14: 33970 | D14: 1993 | E14: 1 | H14: 0.098713584
A15: AT1993Q2 | B15: AT | C15: 34060 | D15: 1993 | E15: 2 | H15: -0.30184725
A16: AT1993Q3 | B16: AT | C16: 34151 | D16: 1993 | E16: 3 | H16: -0.24567407
... A37: AT1998Q4 | B37: AT | C37: 36069 | D37: 1998 | E37: 4 | H37: -1.8649193
A38: AT1999Q1 | B38: AT | C38: 36161 | D38: 1999 | E38: 1 | H38: -1.8447833 | N38: -9.666667
A39: AT1999Q2 | B39: AT | C39: 36251 | D39: 1999 | E39: 2 | H39: -2.0815983 | N39: -10.333333
A40: AT1999Q3 | B40: AT | C40: 36342 | D40: 1999 | E40: 3 | H40: -2.235343 | K40: -0.0013465876 | N40: -8.333333
A41: AT1999Q4 | B41: AT | C41: 36434 | D41: 1999 | E41: 4 | H41: -2.2609696 | K41: -0.89055997 | M41: 69.10791 | N41: -8
A42: AT2000Q1 | B42: AT | C42: 36526 | D42: 2000 | E42: 1 | H42: -1.7285872 | K42: 0.6846447 | M42: 70.107887 | N42: -10.666667
A43: AT2000Q2 | B43: AT | C43: 36617 | D43: 2000 | E43: 2 | H43: -1.3565158 | K43: 0.49886164 | M43: 70.899353 | N43: -10.333333
A44: AT2000Q3 | B44: AT | C44: 36708 | D44: 2000 | E44: 3 | H44: -0.94953936 | K44: 0.93549687 | L44: 5.2345719 | M44: 71.984131 | N44: -12
A45: AT2000Q4 | B45: AT | C45: 36800 | D45: 2000 | E45: 4 | H45: -0.70597112 | K45: -0.15554453 | L45: 5.6487966 | M45: 70.812813 | N45: -10.666667
A46: AT2001Q1 | B46: AT | C46: 36892 | D46: 2001 | E46: 1 | G46: 6.8678226 | H46: -0.82209283 | K46: -1.2931631 | L46: 8.0888634 | M46: 71.499138 | N46: -8
A47: AT2001Q2 | B47: AT | C47: 36982 | D47: 2001 | E47: 2 | G47: 5.7910275 | H47: -1.0768718 | K47: -1.432488 | L47: 8.7615471 | M47: 73.261139 | N47: -8
A48: AT2001Q3 | B48: AT | C48: 37073 | D48: 2001 | E48: 3 | G48: 5.3468804 | H48: -0.9566983 | K48: -0.88149387 | L48: 9.0723801 | M48: 74.946243 | N48: -7.3333335
A49: AT2001Q4 | B49: AT | C49: 37165 | D49: 2001 | E49: 4 | G49: 6.099185 | H49: -0.79628134 | K49: -1.0615997 | L49: 9.0237284 | M49: 72.243065 | N49: -7.3333335
A50: AT2002Q1 | B50: AT | C50: 37257 | D50: 2002 | E50: 1 | G50: 4.2707639 | H50: 0.23902133 | K50: -1.9261531 | L50: 9.9500847 | M50: 72.239693 | N50: -2
A51: AT2002Q2 | B51: AT | C51: 37347 | D51: 2002 | E51: 2 | G51: 3.3535182 | H51: 0.95137608 | K51: -1.8147695 | L51: 9.8006763 | M51: 72.621986 | N51: -2.3333333
A52: AT2002Q3 | B52: AT | C52: 37438 | D52: 2002 | E52: 3 | G52: 2.3107297 | H52: 1.5427232 | K52: -2.2131152 | L52: 10.090236 | M52: 73.553391 | N52: -0.33333334
A53: AT2002Q4 | B53: AT | C53: 37530 | D53: 2002 | E53: 4 | G53: 1.9482249 | H53: 2.1024523 | K53: -2.683042 | L53: 14.656445 | M53: 73.97506 | N53: -2
A54: AT2003Q1 | B54: AT | C54: 37622 | D54: 2003 | E54: 1 | G54: 2.4538388 | H54: 1.9896294 | K54: -2.049763 | L54: 14.24996 | M54: 74.538063 | N54: -0.66666669
A55: AT2003Q2 | B55: AT | C55: 37712 | D55: 2003 | E55: 2 | G55: 2.6291528 | H55: 1.9316751 | K55: -1.8919817 | L55: 13.223071 | M55: 74.589569 | N55: -0.66666669
A56: AT2003Q3 | B56: AT | C56: 37803 | D56: 2003 | E56: 3 | G56: 1.8092209 | H56: 1.5903239 | J56: 0.020598086 | K56: -2.2710526 | L56: 14.260579 | M56: 74.28933 | N56: -0.66666669
A57: AT2003Q4 | B57: AT | C57: 37895 | D57: 2003 | E57: 4 | G57: 2.1717241 | H57: 1.5483316 | J57: -0.16292632 | K57: -0.92385226 | L57: 14.771158 | M57: 74.132782 | N57: -0.33333334
A58: AT2004Q1 | B58: AT | C58: 37987 | D58: 2004 | E58: 1 | G58: 2.478435 | H58: 1.8408493 | J58: -0.461777 | K58: -0.85936618 | L58: 13.056804 | M58: 74.677338 | N58: -4
A59: AT2004Q2 | B59: AT | C59: 38078 | D59: 2004 | E59: 2 | G59: 2.9139874 | H59: 2.2653456 | J59: 0.22162178 | K59: -0.16242951 | L59: 17.727102 | M59: 75.894257 | N59: -1
A60: AT2004Q3 | B60: AT | C60: 38169 | D60: 2004 | E60: 3 | G60: 3.1899488 | H60: 2.2850723 | J60: -0.21952626 | K60: -0.47200689 | L60: 17.467989 | M60: 76.46373 | N60: -2
...

Sheet Metadata
C1: MPR Cyclical Scoreboard
B2: Code | C2: Indicator (untransformed) | D2: Data provider | E2: Dataset
A3: C2 | B3: CTN3R | C3: Total credit (unconsolidated - including trade credit), deflated by CPIP | D3: SDW | E3: QSA, BISM, IEAQ, ICP, MEI
A4: C1 | B4: CBNFA_GDP | C4: Bank credit to NFPS (adjusted by securitisation) to GDP | D4: SDW | E4: BSI, BISM, MNA, ESA
A5: C9 | B5: RRE_HPI_B | C5: Nominal House price-to-income | D5: ECB - DG-E / OECD /SDW | E5: RPV
A6: C3 | B6: CA2GDPEUR | C6: Current account balance to GDP | D6: SDW | E6: BP6, ST1, OEO, MNA, ESA
A7: C11 | B7: DSR | C7: Debt service ratio | D7: SDW/ BIS | E7: QSA, MIR, BSI, MNA
A8: C4 | B8: NLS | C8: Spreads new lending private non-financial sector | D8: SDW | E8: RAI
B10: Methodology: | C10: 2018-05-23 Item 2 MPR technical appendix | D10: MPR
C11: CRAR | D11: CRAR
B13: Code | C13: Underlying indicators | D13: Original frequency | E13: Aggregation method/ observations | F13: Unit | G13: Data provider | H13: Dataset | I13: SDW code | J13: Available in dd-mm-yy (quarter available)
B14: C1 - Bank credit-to-GDP ratio, 2-year av. change | C14: CBNFA: Bank credit to NFPS - adjusted by securitisation (=A+B+C+D)
C15: A: Loans to NFCs - adjusted by securitization | D15: M | E15: end of quarter values | F15: Millions of Euros | G15: SDW | H15: BSI | I15: BSI.M.PT.N.A.A20T.A.1.U6.2240.Z01.E
C16: B: Loans to HHs - adjusted by securitization | D16: M | E16: end of quarter values | F16: Millions of Euros | G16: SDW | H16: BSI | I16: BSI.M.PT.N.A.A20T.A.1.U6.2250.Z01.E
C17: C: Debt securities of NFC | D17: Q | F17: Millions of Euros | G17: SDW | H17: BSI | I17: BSI.Q.PT.N.A.A30.A.1.U6.2240.Z01.E
C18: D: Debt securities of HHs | D18: Q | F18: Millions of Euros | G18: SDW | H18: BSI | I18: BSI.Q.PT.N.A.A30.A.1.U6.2250.Z01.E
C19: Loans + debt securities to nonfin private sector - longer time series | D19: Q | E19: used for backasting* | G19: BIS | I19: https://www.bis.org/statistics/totcredit.htm
C20: GDPN: Gross domestic product, nominal
C21: Gross domestic product, nominal | D21: Q | F21: Millions of Euros | G21: SDW | H21: MNA | I21: MNA.Q.Y.PT.W2.S1.S1.B.B1GQ._Z._Z._Z.XDC.V.N
C22: Gross domestic product, nominal - longer time series | D22: Q | E22: merged with main series for backasting (earlier dates using ECB values since no Haver access) | G22: Haver | H22: Haver | I22: A???GDP@OECDNAQ
B23: C2 - Real total credit, 2-year av. growth | C23: CTHHN: Total credit to HHs (=A+B)
C24: A: QSA loans to HHs, NSA mil. local currency | D24: Q | F24: Millions of Euros | G24: SDW | H24: QSA | I24: QSA.Q.N.PT.W0.S1M.S1.N.L.LE.F4.T._Z.XDC._T.S.V.N._T
C25: B: QSA debt sec issued by HHs, NSA mil. local currency | D25: Q | F25: Millions of Euros | G25: SDW | H25: QSA | I25: QSA.Q.N.PT.W0.S1M.S1.N.L.LE.F3.T._Z.XDC._T.S.V.N._T
C26: Total credit to HHs, longer time series | D26: Q | E26: used for backasting* | G26: SDW | H26: QSA
C27: CTNFCN3: Total credit to NFCs - unconsolidated (including trade credit) (=A+B+C)
C28: A: Total loans to NFCs, NSA mil. local currency | D28: Q | F28: Millions of Euros | G28: SDW | H28: QSA | I28: QSA.Q.N.PT.W0.S11.S1.N.L.LE.F4.T._Z.XDC._T.S.V.N._T
C29: B: Total debt securities issued by NFCs, NSA mil. local currency | D29: Q | F29: Millions of Euros | G29: SDW | H29: QSA | I29: QSA.Q.N.PT.W0.S11.S1.N.L.LE.F3.T._Z.XDC._T.S.V.N._T
C30: C: Total trade credit granted to NFCs, NSA mil. local currency | D30: Q | F30: Millions of Euros | G30: SDW | H30: QSA | I30: QSA.Q.N.PT.W0.S11.S1.N.L.LE.F81.T._Z.XDC._T.S.V.N._T
C31: Total credit to NFC, longer time series | D31: Q | E31: used for backasting* | G31: SDW
C32: CPI
C33: HICP, SA 2015 = 100 | D33: M | E33: average over period | F33: index 2015 = 100 | G33: SDW | H33: ICP | I33: ICP.M.PT.Y.000000.3.INX | J33: 17 working days after the end of the reference month
C34: HICP SA long series, 2010 = 100 | D34: Q | E34: used for backasting* | F34: index 2015 = 100 - rebased | G34: SDW-OECD | H34: MEI | I34: MEI.Q.PT.CPALTT01.IXOB
B35: C3 - Current account balance, % of GDP | C35: CA2GDPEUR: Current account balance to GDP (4Q mov SUM A / 4Q mov SUM B)
C36: Current account (A) | D36: Q | F36: Millions of Euros | G36: SDW | H36: BP6 | I36: BP6.Q.N.PT.W1.S1.S1.T.B.CA._Z._Z._Z.EUR._T._X.N
C37: Current account, long time series | D37: A | E37: used for backasting* / interpolation with annual values | F37: Euros | G37: SDW-OECD | H37: OEO (ecoconomic outlook of OECD) | I37: OEO.Q.PRT.CB
C38: GDPN: Nominal Gross Domestic Product
C39: Nominal Gross Domestic Product (B) | D39: Q | F39: Millions of Euros | G39: SDW | H39: MNA | I39: MNA.Q.N.PT.W2.S1.S1.B.B1GQ._Z._Z._Z.EUR.V.N
D40: A | E40: used for backasting* / interpolation with annual values | F40: Euros | G40: SDW-OECD | H40: OEO (ecoconomic outlook of OECD) | I40: OEO.Q.PT.GDP
B41: C4 - NFPS lending spreads, 2-year av. change | C41: NLS: Spreads new lending private non-financial sector | D41: M | E41: end of quarter values | F41: Percentage points | G41: SDW | H41: RAI | I41: RAI.M.PT.LMGBLNFCH.EUR.MIR.Z
B42: C5 - Bank credit-to-GDP gap | C42: CBNFA: Bank credit to NFPS - adjusted by securitisation (=A+B+C+D)
...

Sheet Metadata_adapted
C1: MPR Cyclical Scoreboard
B2: Code | C2: Indicator (untransformed) | D2: Data provider | E2: Dataset
A3: C2 | B3: CTN3R | C3: Total credit (unconsolidated - including trade credit), deflated by CPIP | D3: SDW | E3: QSA, BISM, IEAQ, ICP, MEI
A4: C1 | B4: CBNFA_GDP | C4: Bank credit to NFPS (adjusted by securitisation) to GDP | D4: SDW | E4: BSI, BISM, MNA, ESA
A5: C9 | B5: RRE_HPI_B | C5: Nominal House price-to-income | D5: ECB - DG-E / OECD /SDW | E5: RPV
A6: C3 | B6: CA2GDPEUR | C6: Current account balance to GDP | D6: SDW | E6: BP6, ST1, OEO, MNA, ESA
A7: C11 | B7: DSR | C7: Debt service ratio | D7: SDW/ BIS | E7: QSA, MIR, BSI, MNA
A8: C4 | B8: NLS | C8: Spreads new lending private non-financial sector | D8: SDW | E8: RAI
B10: Methodology: | C10: 2018-05-23 Item 2 MPR technical appendix | D10: MPR
C11: CRAR | D11: CRAR
B13: Code | C13: Underlying indicators | D13: Original frequency | E13: Aggregation method/ observations | F13: Unit | G13: Data provider | H13: Dataset | I13: SDW code | J13: Available in dd-mm-yy (quarter available)
B14: C1 - Bank credit-to-GDP ratio, 2-year av. change | C14: CBNFA: Bank credit to NFPS - adjusted by securitisation (=A+B+C+D)
C15: A: Loans to NFCs - adjusted by securitization | D15: M | E15: end of quarter values | F15: Millions of Euros | G15: SDW | H15: BSI | I15: BSI.M.PT.N.A.A20T.A.1.U6.2240.Z01.E
C16: B: Loans to HHs - adjusted by securitization | D16: M | E16: end of quarter values | F16: Millions of Euros | G16: SDW | H16: BSI | I16: BSI.M.PT.N.A.A20T.A.1.U6.2250.Z01.E
C17: C: Debt securities of NFC | D17: Q | F17: Millions of Euros | G17: SDW | H17: BSI | I17: BSI.Q.PT.N.A.A30.A.1.U6.2240.Z01.E
C18: D: Debt securities of HHs | D18: Q | F18: Millions of Euros | G18: SDW | H18: BSI | I18: BSI.Q.PT.N.A.A30.A.1.U6.2250.Z01.E
C19: Loans + debt securities to nonfin private sector - longer time series | D19: Q | E19: used for backasting* | G19: BIS | I19: https://www.bis.org/statistics/totcredit.htm
C20: GDPN: Gross domestic product, nominal
C21: Gross domestic product, nominal | D21: Q | F21: Millions of Euros | G21: SDW | H21: MNA | I21: MNA.Q.Y.PT.W2.S1.S1.B.B1GQ._Z._Z._Z.XDC.V.N
C22: Gross domestic product, nominal - longer time series | D22: Q | E22: merged with main series for backasting (earlier dates using ECB values since no Haver access) | G22: Haver | H22: Haver | I22: A???GDP@OECDNAQ
B23: C2 - Real total credit, 2-year av. growth | C23: CTHHN: Total credit to HHs (=A+B)
C24: A: QSA loans to HHs, NSA mil. local currency | D24: Q | F24: Millions of Euros | G24: SDW | H24: QSA | I24: QSA.Q.N.PT.W0.S1M.S1.N.L.LE.F4.T._Z.XDC._T.S.V.N._T
C25: B: QSA debt sec issued by HHs, NSA mil. local currency | D25: Q | F25: Millions of Euros | G25: SDW | H25: QSA | I25: QSA.Q.N.PT.W0.S1M.S1.N.L.LE.F3.T._Z.XDC._T.S.V.N._T
C26: Total credit to HHs, longer time series | D26: Q | E26: used for backasting* | G26: SDW | H26: QSA
C27: CTNFCN3: Total credit to NFCs - unconsolidated (including trade credit) (=A+B+C)
C28: A: Total loans to NFCs, NSA mil. local currency | D28: Q | F28: Millions of Euros | G28: SDW | H28: QSA | I28: QSA.Q.N.PT.W0.S11.S1.N.L.LE.F4.T._Z.XDC._T.S.V.N._T
C29: B: Total debt securities issued by NFCs, NSA mil. local currency | D29: Q | F29: Millions of Euros | G29: SDW | H29: QSA | I29: QSA.Q.N.PT.W0.S11.S1.N.L.LE.F3.T._Z.XDC._T.S.V.N._T
C30: C: Total trade credit granted to NFCs, NSA mil. local currency | D30: Q | F30: Millions of Euros | G30: SDW | H30: QSA | I30: QSA.Q.N.PT.W0.S11.S1.N.L.LE.F81.T._Z.XDC._T.S.V.N._T
C31: Total credit to NFC, longer time series | D31: Q | E31: used for backasting* | G31: SDW
C32: CPI
C33: HICP, SA 2015 = 100 | D33: M | E33: average over period | F33: index 2015 = 100 | G33: SDW | H33: ICP | I33: ICP.M.PT.Y.000000.3.INX | J33: 17 working days after the end of the reference month
C34: HICP SA long series, 2010 = 100 | D34: Q | E34: used for backasting* | F34: index 2015 = 100 - rebased | G34: SDW-OECD | H34: MEI | I34: MEI.Q.PT.CPALTT01.IXOB
B35: C3 - Current account balance, % of GDP | C35: CA2GDPEUR: Current account balance to GDP (4Q mov SUM A / 4Q mov SUM B)
C36: Current account (A) | D36: Q | F36: Millions of Euros | G36: SDW | H36: BP6 | I36: BP6.Q.N.PT.W1.S1.S1.T.B.CA._Z._Z._Z.EUR._T._X.N
C37: Current account, long time series | D37: A | E37: used for backasting* / interpolation with annual values | F37: Euros | G37: SDW-OECD | H37: OEO (ecoconomic outlook of OECD) | I37: OEO.Q.PRT.CB
C38: GDPN: Nominal Gross Domestic Product
C39: Nominal Gross Domestic Product (B) | D39: Q | F39: Millions of Euros | G39: SDW | H39: MNA | I39: MNA.Q.N.PT.W2.S1.S1.B.B1GQ._Z._Z._Z.EUR.V.N
D40: A | E40: used for backasting* / interpolation with annual values | F40: Euros | G40: SDW-OECD | H40: OEO (ecoconomic outlook of OECD) | I40: OEO.Q.PT.GDP
B41: C4 - NFPS lending spreads, 2-year av. change | C41: NLS: Spreads new lending private non-financial sector | D41: M | E41: end of quarter values | F41: Percentage points | G41: SDW | H41: RAI | I41: RAI.M.PT.LMGBLNFCH.EUR.MIR.Z
B42: C5 - Bank credit-to-GDP gap | C42: CBNFA: Bank credit to NFPS - adjusted by securitisation (=A+B+C+D)
...
