Workbook

Sheet data
A1: obstime | B1: sri | C1: shp | D1: bg
A2: 32233 | D2: -0.28064657
A3: 32324 | D3: -0.27589335
A4: 32416 | D4: -0.25768432
A5: 32508 | D5: -0.23157205
A6: 32598 | D6: -0.29788678
A7: 32689 | D7: -0.28261372
A8: 32781 | D8: -0.25466378
A9: 32873 | D9: -0.16846525
A10: 32963 | D10: -0.18066847
A11: 33054 | D11: -0.12823746
A12: 33146 | D12: -0.22171385
A13: 33238 | D13: -0.17139881
A14: 33328 | B14: -0.57855717 | D14: -0.074270703
A15: 33419 | B15: -0.44829189 | D15: -0.011140698
A16: 33511 | B16: -0.4133182 | D16: 0.023297688
A17: 33603 | B17: -0.44555043 | D17: 0.11878495
A18: 33694 | B18: -0.50540327 | D18: 0.073894257
A19: 33785 | B19: -0.53974461 | D19: 0.12062878
A20: 33877 | B20: -0.36170802 | D20: 0.17661853
A21: 33969 | B21: -0.24260625 | D21: 0.25965789
A22: 34059 | B22: -0.23317922 | D22: 0.27869534
A23: 34150 | B23: -0.16042422 | D23: 0.36430239
A24: 34242 | B24: -0.22820113 | D24: 0.36589847
A25: 34334 | B25: -0.23202801 | D25: 0.42408166
... A29: 34699 | B29: -0.23796723 | D29: 0.43733683
A30: 34789 | B30: -0.40128169 | C30: -0.093131606 | D30: 0.43804521
A31: 34880 | B31: -0.47989752 | C31: -0.40565088 | D31: 0.48033807
A32: 34972 | B32: -0.47628897 | C32: -0.33620215 | D32: 0.46184862
A33: 35064 | B33: -0.58922707 | C33: -0.40565088 | D33: 0.51391733
A34: 35155 | B34: -0.44783608 | C34: 0.32356076 | D34: 0.49287252
A35: 35246 | B35: -0.31975963 | C35: 0.51454477 | D35: 0.56227791
A36: 35338 | B36: -0.15021537 | C36: 0.86178841 | D36: 0.59157585
A37: 35430 | B37: -0.039904387 | C37: 1.1903343 | D37: 0.63441183
A38: 35520 | B38: 0.10503832 | C38: 1.408411 | D38: 0.66032034
A39: 35611 | B39: 0.21251919 | C39: 1.4806453 | D39: 0.74250931
A40: 35703 | B40: 0.35243296 | C40: 1.3150177 | D40: 0.81188387
A41: 35795 | B41: 0.50218224 | C41: 1.1639437 | D41: 0.87633371
... A137: 44561 | B137: 0.4577716 | C137: 0.56906693 | D137: -0.75434338
A138: 44651 | B138: 0.25486168 | D138: -0.76085697
...

Sheet summary
B1: "raw" variables | G1: Standardized variables
G2: avg | H2: =+AVERAGE(B7:B147) -> 3.2232281e-17 | I2: =+AVERAGE(C7:C147) -> 0.2515819 | J2: =+AVERAGE(D7:D147) -> 0.47366686 | K2: =+AVERAGE(E7:E147) -> -0.62413942
G3: st dev | H3: =+_xlfn.STDEV.P(B7:B147) -> 1.7234551 | I3: =+_xlfn.STDEV.P(C7:C147) -> 0.72798404 | J3: =+_xlfn.STDEV.P(D7:D147) -> 0.22855733 | K3: =+_xlfn.STDEV.P(E7:E147) -> 21.422051
B6: Factor Model | C6: SRI | D6: Spectral analysis | E6: Basel Gap | H6: Factor Model | I6: SRI | J6: Spectral analysis | K6: Basel Gap
A7: 1988Q1 | E7: =+INDEX('gdp-gap'!B:B,MATCH(summary!A7,'gdp-gap'!A:A,0)) -> -6.6361645 | G7: 32233 | K7: =IF(E7="","",(E7-K$2)/K$3) -> -0.28064657
A8: 1988Q2 | E8: =+INDEX('gdp-gap'!B:B,MATCH(summary!A8,'gdp-gap'!A:A,0)) -> -6.5343407 | G8: 32324 | K8: =IF(E8="","",(E8-K$2)/K$3) -> -0.27589335
A9: 1988Q3 | E9: =+INDEX('gdp-gap'!B:B,MATCH(summary!A9,'gdp-gap'!A:A,0)) -> -6.1442659 | G9: 32416 | K9: =IF(E9="","",(E9-K$2)/K$3) -> -0.25768432
A10: 1988Q4 | E10: =+INDEX('gdp-gap'!B:B,MATCH(summary!A10,'gdp-gap'!A:A,0)) -> -5.5848875 | G10: 32508 | K10: =IF(E10="","",(E10-K$2)/K$3) -> -0.23157205
A11: 1989Q1 | E11: =+INDEX('gdp-gap'!B:B,MATCH(summary!A11,'gdp-gap'!A:A,0)) -> -7.0054851 | G11: 32598 | K11: =IF(E11="","",(E11-K$2)/K$3) -> -0.29788678
A12: 1989Q2 | E12: =+INDEX('gdp-gap'!B:B,MATCH(summary!A12,'gdp-gap'!A:A,0)) -> -6.6783049 | G12: 32689 | K12: =IF(E12="","",(E12-K$2)/K$3) -> -0.28261372
A13: 1989Q3 | E13: =+INDEX('gdp-gap'!B:B,MATCH(summary!A13,'gdp-gap'!A:A,0)) -> -6.0795598 | G13: 32781 | K13: =IF(E13="","",(E13-K$2)/K$3) -> -0.25466378
A14: 1989Q4 | E14: =+INDEX('gdp-gap'!B:B,MATCH(summary!A14,'gdp-gap'!A:A,0)) -> -4.2330105 | G14: 32873 | K14: =IF(E14="","",(E14-K$2)/K$3) -> -0.16846525
A15: 1990Q1 | E15: =+INDEX('gdp-gap'!B:B,MATCH(summary!A15,'gdp-gap'!A:A,0)) -> -4.4944285 | G15: 32963 | K15: =IF(E15="","",(E15-K$2)/K$3) -> -0.18066847
A16: 1990Q2 | E16: =+INDEX('gdp-gap'!B:B,MATCH(summary!A16,'gdp-gap'!A:A,0)) -> -3.3712488 | G16: 33054 | K16: =IF(E16="","",(E16-K$2)/K$3) -> -0.12823746
A17: 1990Q3 | E17: =+INDEX('gdp-gap'!B:B,MATCH(summary!A17,'gdp-gap'!A:A,0)) -> -5.3737048 | G17: 33146 | K17: =IF(E17="","",(E17-K$2)/K$3) -> -0.22171385
A18: 1990Q4 | E18: =+INDEX('gdp-gap'!B:B,MATCH(summary!A18,'gdp-gap'!A:A,0)) -> -4.2958534 | G18: 33238 | K18: =IF(E18="","",(E18-K$2)/K$3) -> -0.17139881
A19: 1991Q1 | C19: =+INDEX(SRI!B:B,MATCH(summary!A19,SRI!A:A,0)) -> -0.16959849 | E19: =+INDEX('gdp-gap'!B:B,MATCH(summary!A19,'gdp-gap'!A:A,0)) -> -2.2151702 | G19: 33328 | I19: =IF(C19="","",(C19-I$2)/I$3) -> -0.57855717 | K19: =IF(E19="","",(E19-K$2)/K$3) -> -0.074270703
A20: 1991Q2 | C20: =+INDEX(SRI!B:B,MATCH(summary!A20,SRI!A:A,0)) -> -0.074767443 | E20: =+INDEX('gdp-gap'!B:B,MATCH(summary!A20,'gdp-gap'!A:A,0)) -> -0.86279603 | G20: 33419 | I20: =IF(C20="","",(C20-I$2)/I$3) -> -0.44829189 | K20: =IF(E20="","",(E20-K$2)/K$3) -> -0.011140698
A21: 1991Q3 | C21: =+INDEX(SRI!B:B,MATCH(summary!A21,SRI!A:A,0)) -> -0.049307158 | E21: =+INDEX('gdp-gap'!B:B,MATCH(summary!A21,'gdp-gap'!A:A,0)) -> -0.12505516 | G21: 33511 | I21: =IF(C21="","",(C21-I$2)/I$3) -> -0.4133182 | K21: =IF(E21="","",(E21-K$2)/K$3) -> 0.023297688
A22: 1991Q4 | C22: =+INDEX(SRI!B:B,MATCH(summary!A22,SRI!A:A,0)) -> -0.072771706 | E22: =+INDEX('gdp-gap'!B:B,MATCH(summary!A22,'gdp-gap'!A:A,0)) -> 1.9204779 | G22: 33603 | I22: =IF(C22="","",(C22-I$2)/I$3) -> -0.44555043 | K22: =IF(E22="","",(E22-K$2)/K$3) -> 0.11878495
A23: 1992Q1 | C23: =+INDEX(SRI!B:B,MATCH(summary!A23,SRI!A:A,0)) -> -0.11634361 | E23: =+INDEX('gdp-gap'!B:B,MATCH(summary!A23,'gdp-gap'!A:A,0)) -> 0.9588271 | G23: 33694 | I23: =IF(C23="","",(C23-I$2)/I$3) -> -0.50540327 | K23: =IF(E23="","",(E23-K$2)/K$3) -> 0.073894257
A24: 1992Q2 | C24: =+INDEX(SRI!B:B,MATCH(summary!A24,SRI!A:A,0)) -> -0.14134356 | E24: =+INDEX('gdp-gap'!B:B,MATCH(summary!A24,'gdp-gap'!A:A,0)) -> 1.9599765 | G24: 33785 | I24: =IF(C24="","",(C24-I$2)/I$3) -> -0.53974461 | K24: =IF(E24="","",(E24-K$2)/K$3) -> 0.12062878
A25: 1992Q3 | C25: =+INDEX(SRI!B:B,MATCH(summary!A25,SRI!A:A,0)) -> -0.011735765 | E25: =+INDEX('gdp-gap'!B:B,MATCH(summary!A25,'gdp-gap'!A:A,0)) -> 3.1593916 | G25: 33877 | I25: =IF(C25="","",(C25-I$2)/I$3) -> -0.36170802 | K25: =IF(E25="","",(E25-K$2)/K$3) -> 0.17661853
A26: 1992Q4 | C26: =+INDEX(SRI!B:B,MATCH(summary!A26,SRI!A:A,0)) -> 0.074968417 | E26: =+INDEX('gdp-gap'!B:B,MATCH(summary!A26,'gdp-gap'!A:A,0)) -> 4.938265 | G26: 33969 | I26: =IF(C26="","",(C26-I$2)/I$3) -> -0.24260625 | K26: =IF(E26="","",(E26-K$2)/K$3) -> 0.25965789
A27: 1993Q1 | C27: =+INDEX(SRI!B:B,MATCH(summary!A27,SRI!A:A,0)) -> 0.081831147 | E27: =+INDEX('gdp-gap'!B:B,MATCH(summary!A27,'gdp-gap'!A:A,0)) -> 5.3460862 | G27: 34059 | I27: =IF(C27="","",(C27-I$2)/I$3) -> -0.23317922 | K27: =IF(E27="","",(E27-K$2)/K$3) -> 0.27869534
A28: 1993Q2 | C28: =+INDEX(SRI!B:B,MATCH(summary!A28,SRI!A:A,0)) -> 0.13479562 | E28: =+INDEX('gdp-gap'!B:B,MATCH(summary!A28,'gdp-gap'!A:A,0)) -> 7.1799649 | G28: 34150 | I28: =IF(C28="","",(C28-I$2)/I$3) -> -0.16042422 | K28: =IF(E28="","",(E28-K$2)/K$3) -> 0.36430239
A29: 1993Q3 | C29: =+INDEX(SRI!B:B,MATCH(summary!A29,SRI!A:A,0)) -> 0.085455119 | E29: =+INDEX('gdp-gap'!B:B,MATCH(summary!A29,'gdp-gap'!A:A,0)) -> 7.2141561 | G29: 34242 | I29: =IF(C29="","",(C29-I$2)/I$3) -> -0.22820113 | K29: =IF(E29="","",(E29-K$2)/K$3) -> 0.36589847
A30: 1993Q4 | C30: =+INDEX(SRI!B:B,MATCH(summary!A30,SRI!A:A,0)) -> 0.082669212 | E30: =+INDEX('gdp-gap'!B:B,MATCH(summary!A30,'gdp-gap'!A:A,0)) -> 8.4605593 | G30: 34334 | I30: =IF(C30="","",(C30-I$2)/I$3) -> -0.23202801 | K30: =IF(E30="","",(E30-K$2)/K$3) -> 0.42408166
... A34: 1994Q4 | C34: =+INDEX(SRI!B:B,MATCH(summary!A34,SRI!A:A,0)) -> 0.07834555 | E34: =+INDEX('gdp-gap'!B:B,MATCH(summary!A34,'gdp-gap'!A:A,0)) -> 8.7445124 | G34: 34699 | I34: =IF(C34="","",(C34-I$2)/I$3) -> -0.23796723 | K34: =IF(E34="","",(E34-K$2)/K$3) -> 0.43733683
A35: 1995Q1 | C35: =+INDEX(SRI!B:B,MATCH(summary!A35,SRI!A:A,0)) -> -0.040544769 | D35: =+INDEX(schuler!E:E,MATCH(summary!A35,schuler!C:C,0)) -> 0.45238095 | E35: =+INDEX('gdp-gap'!B:B,MATCH(summary!A35,'gdp-gap'!A:A,0)) -> 8.7596872 | G35: 34789 | I35: =IF(C35="","",(C35-I$2)/I$3) -> -0.40128169 | J35: =IF(D35="","",(D35-J$2)/J$3) -> -0.093131606 | K35: =IF(E35="","",(E35-K$2)/K$3) -> 0.43804521
A36: 1995Q2 | C36: =+INDEX(SRI!B:B,MATCH(summary!A36,SRI!A:A,0)) -> -0.097775835 | D36: =+INDEX(schuler!E:E,MATCH(summary!A36,schuler!C:C,0)) -> 0.38095238 | E36: =+INDEX('gdp-gap'!B:B,MATCH(summary!A36,'gdp-gap'!A:A,0)) -> 9.6656871 | G36: 34880 | I36: =IF(C36="","",(C36-I$2)/I$3) -> -0.47989752 | J36: =IF(D36="","",(D36-J$2)/J$3) -> -0.40565088 | K36: =IF(E36="","",(E36-K$2)/K$3) -> 0.48033807
A37: 1995Q3 | C37: =+INDEX(SRI!B:B,MATCH(summary!A37,SRI!A:A,0)) -> -0.095148866 | D37: =+INDEX(schuler!E:E,MATCH(summary!A37,schuler!C:C,0)) -> 0.3968254 | E37: =+INDEX('gdp-gap'!B:B,MATCH(summary!A37,'gdp-gap'!A:A,0)) -> 9.2696051 | G37: 34972 | I37: =IF(C37="","",(C37-I$2)/I$3) -> -0.47628897 | J37: =IF(D37="","",(D37-J$2)/J$3) -> -0.33620215 | K37: =IF(E37="","",(E37-K$2)/K$3) -> 0.46184862
A38: 1995Q4 | C38: =+INDEX(SRI!B:B,MATCH(summary!A38,SRI!A:A,0)) -> -0.177366 | D38: =+INDEX(schuler!E:E,MATCH(summary!A38,schuler!C:C,0)) -> 0.38095238 | E38: =+INDEX('gdp-gap'!B:B,MATCH(summary!A38,'gdp-gap'!A:A,0)) -> 10.385024 | G38: 35064 | I38: =IF(C38="","",(C38-I$2)/I$3) -> -0.58922707 | J38: =IF(D38="","",(D38-J$2)/J$3) -> -0.40565088 | K38: =IF(E38="","",(E38-K$2)/K$3) -> 0.51391733
A39: 1996Q1 | C39: =+INDEX(SRI!B:B,MATCH(summary!A39,SRI!A:A,0)) -> -0.074435621 | D39: =+INDEX(schuler!E:E,MATCH(summary!A39,schuler!C:C,0)) -> 0.54761905 | E39: =+INDEX('gdp-gap'!B:B,MATCH(summary!A39,'gdp-gap'!A:A,0)) -> 9.9342008 | G39: 35155 | I39: =IF(C39="","",(C39-I$2)/I$3) -> -0.44783608 | J39: =IF(D39="","",(D39-J$2)/J$3) -> 0.32356076 | K39: =IF(E39="","",(E39-K$2)/K$3) -> 0.49287252
A40: 1996Q2 | C40: =+INDEX(SRI!B:B,MATCH(summary!A40,SRI!A:A,0)) -> 0.018801992 | D40: =+INDEX(schuler!E:E,MATCH(summary!A40,schuler!C:C,0)) -> 0.59126984 | E40: =+INDEX('gdp-gap'!B:B,MATCH(summary!A40,'gdp-gap'!A:A,0)) -> 11.421007 | G40: 35246 | I40: =IF(C40="","",(C40-I$2)/I$3) -> -0.31975963 | J40: =IF(D40="","",(D40-J$2)/J$3) -> 0.51454477 | K40: =IF(E40="","",(E40-K$2)/K$3) -> 0.56227791
A41: 1996Q3 | C41: =+INDEX(SRI!B:B,MATCH(summary!A41,SRI!A:A,0)) -> 0.14222751 | D41: =+INDEX(schuler!E:E,MATCH(summary!A41,schuler!C:C,0)) -> 0.67063492 | E41: =+INDEX('gdp-gap'!B:B,MATCH(summary!A41,'gdp-gap'!A:A,0)) -> 12.048629 | G41: 35338 | I41: =IF(C41="","",(C41-I$2)/I$3) -> -0.15021537 | J41: =IF(D41="","",(D41-J$2)/J$3) -> 0.86178841 | K41: =IF(E41="","",(E41-K$2)/K$3) -> 0.59157585
A42: 1996Q4 | C42: =+INDEX(SRI!B:B,MATCH(summary!A42,SRI!A:A,0)) -> 0.22253214 | D42: =+INDEX(schuler!E:E,MATCH(summary!A42,schuler!C:C,0)) -> 0.7457265 | E42: =+INDEX('gdp-gap'!B:B,MATCH(summary!A42,'gdp-gap'!A:A,0)) -> 12.966263 | G42: 35430 | I42: =IF(C42="","",(C42-I$2)/I$3) -> -0.039904387 | J42: =IF(D42="","",(D42-J$2)/J$3) -> 1.1903343 | K42: =IF(E42="","",(E42-K$2)/K$3) -> 0.63441183
A43: 1997Q1 | C43: =+INDEX(SRI!B:B,MATCH(summary!A43,SRI!A:A,0)) -> 0.32804812 | D43: =+INDEX(schuler!E:E,MATCH(summary!A43,schuler!C:C,0)) -> 0.79556951 | E43: =+INDEX('gdp-gap'!B:B,MATCH(summary!A43,'gdp-gap'!A:A,0)) -> 13.521276 | G43: 35520 | I43: =IF(C43="","",(C43-I$2)/I$3) -> 0.10503832 | J43: =IF(D43="","",(D43-J$2)/J$3) -> 1.408411 | K43: =IF(E43="","",(E43-K$2)/K$3) -> 0.66032034
A44: 1997Q2 | C44: =+INDEX(SRI!B:B,MATCH(summary!A44,SRI!A:A,0)) -> 0.40629248 | D44: =+INDEX(schuler!E:E,MATCH(summary!A44,schuler!C:C,0)) -> 0.81207919 | E44: =+INDEX('gdp-gap'!B:B,MATCH(summary!A44,'gdp-gap'!A:A,0)) -> 15.281933 | G44: 35611 | I44: =IF(C44="","",(C44-I$2)/I$3) -> 0.21251919 | J44: =IF(D44="","",(D44-J$2)/J$3) -> 1.4806453 | K44: =IF(E44="","",(E44-K$2)/K$3) -> 0.74250931
A45: 1997Q3 | C45: =+INDEX(SRI!B:B,MATCH(summary!A45,SRI!A:A,0)) -> 0.50814746 | D45: =+INDEX(schuler!E:E,MATCH(summary!A45,schuler!C:C,0)) -> 0.77422379 | E45: =+INDEX('gdp-gap'!B:B,MATCH(summary!A45,'gdp-gap'!A:A,0)) -> 16.768078 | G45: 35703 | I45: =IF(C45="","",(C45-I$2)/I$3) -> 0.35243296 | J45: =IF(D45="","",(D45-J$2)/J$3) -> 1.3150177 | K45: =IF(E45="","",(E45-K$2)/K$3) -> 0.81188387
...

Sheet FM
D1: Q | E1: av_FC | F1: av_FC_2
A2: =+LEFT(D2,4) -> 1988 | B2: 1 | C2: =+A2&"Q"&B2 -> 1988Q1 | D2: 1988 | E2: -0.49424101
A3: =+LEFT(D3,4) -> 1988 | B3: 2 | C3: =+A3&"Q"&B3 -> 1988Q2 | D3: 1988.25 | E3: -0.5454994
A4: =+LEFT(D4,4) -> 1988 | B4: 3 | C4: =+A4&"Q"&B4 -> 1988Q3 | D4: 1988.5 | E4: -0.57796689
A5: =+LEFT(D5,4) -> 1988 | B5: 4 | C5: =+A5&"Q"&B5 -> 1988Q4 | D5: 1988.75 | E5: -0.58256651
A6: =+LEFT(D6,4) -> 1989 | B6: =+B2 -> 1 | C6: =+A6&"Q"&B6 -> 1989Q1 | D6: 1989 | E6: -0.55306285
A7: =+LEFT(D7,4) -> 1989 | B7: =+B3 -> 2 | C7: =+A7&"Q"&B7 -> 1989Q2 | D7: 1989.25 | E7: -0.48620746
A8: =+LEFT(D8,4) -> 1989 | B8: =+B4 -> 3 | C8: =+A8&"Q"&B8 -> 1989Q3 | D8: 1989.5 | E8: -0.38205143
A9: =+LEFT(D9,4) -> 1989 | B9: =+B5 -> 4 | C9: =+A9&"Q"&B9 -> 1989Q4 | D9: 1989.75 | E9: -0.24408646
A10: =+LEFT(D10,4) -> 1990 | B10: =+B6 -> 1 | C10: =+A10&"Q"&B10 -> 1990Q1 | D10: 1990 | E10: -0.079158098
A11: =+LEFT(D11,4) -> 1990 | B11: =+B7 -> 2 | C11: =+A11&"Q"&B11 -> 1990Q2 | D11: 1990.25 | E11: 0.1028747
A12: =+LEFT(D12,4) -> 1990 | B12: =+B8 -> 3 | C12: =+A12&"Q"&B12 -> 1990Q3 | D12: 1990.5 | E12: 0.28973142
A13: =+LEFT(D13,4) -> 1990 | B13: =+B9 -> 4 | C13: =+A13&"Q"&B13 -> 1990Q4 | D13: 1990.75 | E13: 0.46752406
A14: =+LEFT(D14,4) -> 1991 | B14: =+B10 -> 1 | C14: =+A14&"Q"&B14 -> 1991Q1 | D14: 1991 | E14: 0.62174065
A15: =+LEFT(D15,4) -> 1991 | B15: =+B11 -> 2 | C15: =+A15&"Q"&B15 -> 1991Q2 | D15: 1991.25 | E15: 0.73832653
A16: =+LEFT(D16,4) -> 1991 | B16: =+B12 -> 3 | C16: =+A16&"Q"&B16 -> 1991Q3 | D16: 1991.5 | E16: 0.80477988
A17: =+LEFT(D17,4) -> 1991 | B17: =+B13 -> 4 | C17: =+A17&"Q"&B17 -> 1991Q4 | D17: 1991.75 | E17: 0.81117321
... A61: =+LEFT(D61,4) -> 2002 | B61: =+B57 -> 4 | C61: =+A61&"Q"&B61 -> 2002Q4 | D61: 2002.75 | E61: -0.96694531
A62: =+LEFT(D62,4) -> 2003 | B62: =+B58 -> 1 | C62: =+A62&"Q"&B62 -> 2003Q1 | D62: 2003 | E62: -1.2643588 | F62: -1.0564211
A63: =+LEFT(D63,4) -> 2003 | B63: =+B59 -> 2 | C63: =+A63&"Q"&B63 -> 2003Q2 | D63: 2003.25 | E63: -1.4989584 | F63: -1.2029364
A64: =+LEFT(D64,4) -> 2003 | B64: =+B60 -> 3 | C64: =+A64&"Q"&B64 -> 2003Q3 | D64: 2003.5 | E64: -1.6619642 | F64: -1.294702
A65: =+LEFT(D65,4) -> 2003 | B65: =+B61 -> 4 | C65: =+A65&"Q"&B65 -> 2003Q4 | D65: 2003.75 | E65: -1.7478463 | F65: -1.3251803
A66: =+LEFT(D66,4) -> 2004 | B66: =+B62 -> 1 | C66: =+A66&"Q"&B66 -> 2004Q1 | D66: 2004 | E66: -1.7546997 | F66: -1.2903469
A67: =+LEFT(D67,4) -> 2004 | B67: =+B63 -> 2 | C67: =+A67&"Q"&B67 -> 2004Q2 | D67: 2004.25 | E67: -1.6844 | F67: -1.1893164
A68: =+LEFT(D68,4) -> 2004 | B68: =+B64 -> 3 | C68: =+A68&"Q"&B68 -> 2004Q3 | D68: 2004.5 | E68: -1.5425171 | F68: -1.0246114
A69: =+LEFT(D69,4) -> 2004 | B69: =+B65 -> 4 | C69: =+A69&"Q"&B69 -> 2004Q4 | D69: 2004.75 | E69: -1.337987 | F69: -0.80218619
A70: =+LEFT(D70,4) -> 2005 | B70: =+B66 -> 1 | C70: =+A70&"Q"&B70 -> 2005Q1 | D70: 2005 | E70: -1.0825595 | F70: -0.53119553
A71: =+LEFT(D71,4) -> 2005 | B71: =+B67 -> 2 | C71: =+A71&"Q"&B71 -> 2005Q2 | D71: 2005.25 | E71: -0.79006367 | F71: -0.22352486
A72: =+LEFT(D72,4) -> 2005 | B72: =+B68 -> 3 | C72: =+A72&"Q"&B72 -> 2005Q3 | D72: 2005.5 | E72: -0.47554384 | F72: 0.10688878
A73: =+LEFT(D73,4) -> 2005 | B73: =+B69 -> 4 | C73: =+A73&"Q"&B73 -> 2005Q4 | D73: 2005.75 | E73: -0.15433487 | F73: 0.44489325
... A142: =+LEFT(D142,4) -> 2023 | B142: =+B138 -> 1 | C142: =+A142&"Q"&B142 -> 2023Q1 | D142: 2023 | E142: 0.78027904 | F142: 0.94833274

Sheet SRI
A1: date | B1: CI normalized with pooled data
A2: 1991Q1 | B2: -0.16959849
A3: 1991Q2 | B3: -0.074767443
A4: 1991Q3 | B4: -0.049307158
A5: 1991Q4 | B5: -0.072771706
A6: 1992Q1 | B6: -0.11634361
A7: 1992Q2 | B7: -0.14134356
A8: 1992Q3 | B8: -0.011735765
A9: 1992Q4 | B9: 0.074968417
A10: 1993Q1 | B10: 0.081831147
A11: 1993Q2 | B11: 0.13479562
A12: 1993Q3 | B12: 0.085455119
A13: 1993Q4 | B13: 0.082669212
... A129: 2022Q4 | B129: -0.37068945

Sheet schuler
D1: Row | E1: PRT
A2: =+LEFT(D2,4) -> 1995 | B2: 1 | C2: =+A2&"Q"&B2 -> 1995Q1 | D2: 19951 | E2: 0.45238095
A3: =+LEFT(D3,4) -> 1995 | B3: 2 | C3: =+A3&"Q"&B3 -> 1995Q2 | D3: 19952 | E3: 0.38095238
A4: =+LEFT(D4,4) -> 1995 | B4: 3 | C4: =+A4&"Q"&B4 -> 1995Q3 | D4: 19953 | E4: 0.3968254
A5: =+LEFT(D5,4) -> 1995 | B5: 4 | C5: =+A5&"Q"&B5 -> 1995Q4 | D5: 19954 | E5: 0.38095238
A6: =+LEFT(D6,4) -> 1996 | B6: =+B2 -> 1 | C6: =+A6&"Q"&B6 -> 1996Q1 | D6: 19961 | E6: 0.54761905
A7: =+LEFT(D7,4) -> 1996 | B7: =+B3 -> 2 | C7: =+A7&"Q"&B7 -> 1996Q2 | D7: 19962 | E7: 0.59126984
A8: =+LEFT(D8,4) -> 1996 | B8: =+B4 -> 3 | C8: =+A8&"Q"&B8 -> 1996Q3 | D8: 19963 | E8: 0.67063492
A9: =+LEFT(D9,4) -> 1996 | B9: =+B5 -> 4 | C9: =+A9&"Q"&B9 -> 1996Q4 | D9: 19964 | E9: 0.7457265
A10: =+LEFT(D10,4) -> 1997 | B10: =+B6 -> 1 | C10: =+A10&"Q"&B10 -> 1997Q1 | D10: 19971 | E10: 0.79556951
A11: =+LEFT(D11,4) -> 1997 | B11: =+B7 -> 2 | C11: =+A11&"Q"&B11 -> 1997Q2 | D11: 19972 | E11: 0.81207919
A12: =+LEFT(D12,4) -> 1997 | B12: =+B8 -> 3 | C12: =+A12&"Q"&B12 -> 1997Q3 | D12: 19973 | E12: 0.77422379
A13: =+LEFT(D13,4) -> 1997 | B13: =+B9 -> 4 | C13: =+A13&"Q"&B13 -> 1997Q4 | D13: 19974 | E13: 0.73969472
A14: =+LEFT(D14,4) -> 1998 | B14: =+B10 -> 1 | C14: =+A14&"Q"&B14 -> 1998Q1 | D14: 19981 | E14: 0.77519367
A15: =+LEFT(D15,4) -> 1998 | B15: =+B11 -> 2 | C15: =+A15&"Q"&B15 -> 1998Q2 | D15: 19982 | E15: 0.73056173
A16: =+LEFT(D16,4) -> 1998 | B16: =+B12 -> 3 | C16: =+A16&"Q"&B16 -> 1998Q3 | D16: 19983 | E16: 0.58712508
A17: =+LEFT(D17,4) -> 1998 | B17: =+B13 -> 4 | C17: =+A17&"Q"&B17 -> 1998Q4 | D17: 19984 | E17: 0.49640953
... A109: =+LEFT(D109,4) -> 2021 | B109: =+B105 -> 4 | C109: =+A109&"Q"&B109 -> 2021Q4 | D109: 20214 | E109: 0.60373128

Sheet gdp-gap
A2: Date | B2: Bank credit to non-financial private sector
A3: 1977Q1
A4: 1977Q2
A5: 1977Q3
A6: 1977Q4
A7: 1978Q1
A8: 1978Q2
A9: 1978Q3 | B9: -0.62032273
A10: 1978Q4 | B10: -0.22994243
A11: 1979Q1 | B11: -1.1957539
A12: 1979Q2 | B12: -0.37484957
A13: 1979Q3 | B13: -0.79547719
A14: 1979Q4 | B14: 0.26916008
A15: 1980Q1 | B15: 0.51659836
A16: 1980Q2 | B16: -0.58241712
A17: 1980Q3 | B17: -0.63439355
A18: 1980Q4 | B18: 1.7431116
A19: 1981Q1 | B19: 2.617279
A20: 1981Q2 | B20: 3.8643
... A186: 2022Q4 | B186: -19.293193
A187: 2023Q1
A188: 2023Q2
A189: 2023Q3
A190: 2023Q4
A191: 2024Q1
A192: 2024Q2
A193: 2024Q3
A194: 2024Q4
A195: 2025Q1
A196: 2025Q2
A197: 2025Q3
A198: 2025Q4
... A258: 2040Q4
